<?xml version="1.0"?>
<robot xmlns:xacro="http://www.ros.org/wiki/xacro">
  <link name="base_link">
    <origin rpy="0 0 0" xyz="0 0 0" />
  </link>
  <link
    name="chassis">
    <inertial>
      <origin
        xyz="0.0374140021041951 -0.000373005187591258 -0.0771282894414029"
        rpy="0 0 0" />
      <mass
        value="24.73" />
      <inertia
        ixx="0.123215829336501"
        ixy="-2.51201031615063E-06"
        ixz="0.00480100638469038"
        iyy="0.219144715482931"
        iyz="-1.0329581476775E-05"
        izz="0.313606030126045" />
    </inertial>
    <visual>
      <origin
        xyz="0 0 0"
        rpy="0 0 0" />
      <geometry>
        <mesh
          filename="package://hunter_description/meshes/base_link.STL" />
      </geometry>
      <material
        name="">
        <color
          rgba="0.752941176470588 0.752941176470588 0.752941176470588 1" />
      </material>
    </visual>
    <collision>
      <origin
        xyz="0 0 0"
        rpy="0 0 0" />
      <geometry>
        <mesh
          filename="package://hunter_description/meshes/base_link.STL" />
      </geometry>
    </collision>
  </link>
  <joint name="base_link_joint" type="fixed">
    <parent link="base_link" />
    <child link="chassis" />
  </joint>
  <link
    name="fr_steer_left_link">
    <inertial>
      <origin
        xyz="-0.0002776492198312 0.0163539773588368 4.97346169803237E-09"
        rpy="0 0 0" />
      <mass
        value="3.149" />
      <inertia
        ixx="0.0222"
        ixy="0.0"
        ixz="0.0"
        iyy="0.0222"
        iyz="0.0"
        izz="0.0378075" />
    </inertial>
    <visual>
      <origin
        xyz="0 0 0"
        rpy="0 0 0" />
      <geometry>
        <box size="0.001 0.001 0.001"/>
      </geometry>
      <material
        name="">
        <color
          rgba="0.223529411764706 0.223529411764706 0.223529411764706 1" />
      </material>
    </visual>
    <collision>
      <origin
        xyz="0 0 0"
        rpy="0 0 0" />
      <geometry>
        <box size="0.001 0.001 0.001"/>
      </geometry>
    </collision>
  </link>
  <joint
    name="fr_steer_left_joint"
    type="revolute">
    <origin
      xyz="0.34058 0.24619 -0.1535"
      rpy="0 0 0" />
    <parent
      link="base_link" />
    <child
      link="fr_steer_left_link" />
    <axis
      xyz="0 0 1" />
    <limit
      lower="-0.69"
      upper="0.69"
      effort="0"
      velocity="0" />
  </joint>
  <link
    name="fr_left_link">
    <inertial>
      <origin
        xyz="-3.5837499634539E-10 4.97346158701006E-09 -0.016356334080185"
        rpy="0 0 0" />
      <mass
        value="3.149" />
      <inertia
        ixx="0.0222"
        ixy="0.0"
        ixz="0.0"
        iyy="0.0222"
        iyz="0.0"
        izz="0.0378075" />
    </inertial>
    <visual>
      <origin
        xyz="0 0 0"
        rpy="0 0 0" />
      <geometry>
        <mesh
          filename="package://hunter_description/meshes/fr_left_link.STL" />
      </geometry>
      <material
        name="">
        <color
          rgba="0.223529411764706 0.223529411764706 0.223529411764706 1" />
      </material>
    </visual>
    <collision>
      <origin
        xyz="0 0 0"
        rpy="0 0 0" />
      <geometry>
        <mesh
          filename="package://hunter_description/meshes/fr_left_link.STL" />
      </geometry>
    </collision>
  </link>
  <joint
    name="fr_left_joint"
    type="continuous">
    <origin
      xyz="0 0 0"
      rpy="1.5708 0 0.016976" />
    <parent
      link="fr_steer_left_link" />
    <child
      link="fr_left_link" />
    <axis
      xyz="0 0 -1" />
     <dynamics damping="0.0" friction="15"/>      
  </joint>
  <link
    name="fr_steer_right_link">
    <inertial>
      <origin
        xyz="0.000274981985673328 -0.0163540222836661 -3.24802407192237E-11"
        rpy="0 0 0" />
      <mass
        value="3.149" />
      <inertia
        ixx="0.0222"
        ixy="0.0"
        ixz="0.0"
        iyy="0.0222"
        iyz="0.0"
        izz="0.0378075" />
    </inertial>
    <visual>
      <origin
        xyz="0 0 0"
        rpy="0 0 0" />
      <geometry>
        <box size="0.001 0.001 0.001"/>
      </geometry>
      <material
        name="">
        <color
          rgba="1 1 1 1" />
      </material>
    </visual>
    <collision>
      <origin
        xyz="0 0 0"
        rpy="0 0 0" />
      <geometry>
        <box size="0.001 0.001 0.001"/>
      </geometry>
    </collision>
  </link>
  <joint
    name="fr_steer_right_joint"
    type="revolute">
    <origin
      xyz="0.34219 -0.24619 -0.1535"
      rpy="0 0 0" />
    <parent
      link="chassis" />
    <child
      link="fr_steer_right_link" />
    <axis
      xyz="0 0 1" />
    <limit
      lower="-0.69"
      upper="0.69"
      effort="0"
      velocity="0" />
  </joint>
  <link
    name="fr_right_link">
    <inertial>
      <origin
        xyz="0.00027498198567355 3.24801296969213E-11 -0.0163540222836661"
        rpy="0 0 0" />
      <mass
        value="3.149" />
      <inertia
        ixx="0.0222"
        ixy="0.0"
        ixz="0.0"
        iyy="0.0222"
        iyz="0.0"
        izz="0.0378075" />
    </inertial>
    <visual>
      <origin
        xyz="0 0 0"
        rpy="0 0 0" />
      <geometry>
        <mesh
          filename="package://hunter_description/meshes/fr_right_link.STL" />
      </geometry>
      <material
        name="">
        <color
          rgba="0.223529411764706 0.223529411764706 0.223529411764706 1" />
      </material>
    </visual>
    <collision>
      <origin
        xyz="0 0 0"
        rpy="0 0 0" />
      <geometry>
        <mesh
          filename="package://hunter_description/meshes/fr_right_link.STL" />
      </geometry>
    </collision>
  </link>
  <joint
    name="fr_right_joint"
    type="continuous">
    <origin
      xyz="0 0 0"
      rpy="-1.5708 0 0" />
    <parent
      link="fr_steer_right_link" />
    <child
      link="fr_right_link" />
    <axis
      xyz="0 0 1" />
    <dynamics damping="0.0" friction="15"/>
  </joint>

  <link
    name="re_left_link">
    <inertial>
      <origin
        xyz="1.245E-09 1.7252E-06 -0.010284"
        rpy="0 0 0" />
      <mass
        value="3.149" />
      <inertia
        ixx="0.0222"
        ixy="0.0"
        ixz="0.0"
        iyy="0.0222"
        iyz="0.0"
        izz="0.0378075" />
    </inertial>
    <visual>
      <origin
        xyz="0 0 0"
        rpy="0 0 0" />
      <geometry>
        <mesh
          filename="package://hunter_description/meshes/re_left_link.STL" />
      </geometry>
      <material
        name="">
        <color
          rgba="0.37647 0.37647 0.37647 1" />
      </material>
    </visual>
    <collision>
      <origin
        xyz="0 0 0"
        rpy="0 0 0" />
      <geometry>
        <mesh
          filename="package://hunter_description/meshes/re_left_link.STL" />
      </geometry>
    </collision>
  </link>
  <joint
    name="re_left_joint"
    type="continuous">
    <origin
      xyz="-0.2078 0.252 -0.158"
      rpy="1.5708 0 0" />
    <parent
      link="chassis" />
    <child
      link="re_left_link" />
    <axis
      xyz="0 0 -1" />
    <dynamics damping="0.0" friction="15"/>
  </joint>
  <link
    name="re_right_link">
    <inertial>
      <origin
        xyz="0 0 0"
        rpy="0 0 0" />
      <mass
        value="3.149" />
      <inertia
        ixx="0.0222"
        ixy="0.0"
        ixz="0.0"
        iyy="0.0222"
        iyz="0.0"
        izz="0.0378075" />
    </inertial>
    <visual>
      <origin
        xyz="0 0 0"
        rpy="0 0 0" />
      <geometry>
        <mesh
          filename="package://hunter_description/meshes/re_right_link.STL" />
      </geometry>
      <material
        name="">
        <color
          rgba="1 1 1 1" />
      </material>
    </visual>
    <collision>
      <origin
        xyz="0 0 0"
        rpy="0 0 0" />
      <geometry>
        <mesh
          filename="package://hunter_description/meshes/re_right_link.STL" />
      </geometry>
    </collision>
  </link>
  <joint
    name="re_right_joint"
    type="continuous">
    <origin
      xyz="-0.2078 -0.252 -0.158"
      rpy="-1.5708 0 0" />
    <parent
      link="chassis" />
    <child
      link="re_right_link" />
    <axis
      xyz="0 0 1" />
    <dynamics damping="0.0" friction="15"/>
  </joint>
</robot>
